Workbook

Sheet OD+pH
A1: Donor | B1: Supplement mix | C1: initial pH | D1: 48h pH | E1: pH diff | F1: Corrected OD
A2: D6 | B2: H2O | C2: 4.8 | D2: 4.78 | E2: =D2-C2 -> -0.02 | F2: -0.0231
A3: D6 | B3: H2O | C3: 4.8 | D3: 4.81 | E3: =D3-C3 -> 0.01 | F3: -0.020000003
A4: D6 | B4: H2O | C4: 4.8 | D4: 4.82 | E4: =D4-C4 -> 0.02 | F4: -0.022200003
A5: D6 | B5: HMOs | C5: 4.8 | D5: 4.81 | E5: =D5-C5 -> 0.01 | F5: 0.074300006
A6: D6 | B6: HMOs | C6: 4.8 | D6: 5.88 | E6: =D6-C6 -> 1.08 | F6: 0.070600003
A7: D6 | B7: HMOs | C7: 4.8 | D7: 4.79 | E7: =D7-C7 -> -0.01 | F7: 0.078400001
A8: D6 | B8: GOS | C8: 4.8 | D8: 4.55 | E8: =D8-C8 -> -0.25 | F8: 0.1512
A9: D6 | B9: GOS | C9: 4.8 | D9: 4.55 | E9: =D9-C9 -> -0.25 | F9: 0.1411
A10: D6 | B10: GOS | C10: 4.8 | D10: 4.56 | E10: =D10-C10 -> -0.24 | F10: 0.1329
A11: D6 | B11: HMOs+GOS | C11: 4.8 | D11: 4.58 | E11: =D11-C11 -> -0.22 | F11: 0.15089999
A12: D6 | B12: HMOs+GOS | C12: 4.8 | D12: 4.62 | E12: =D12-C12 -> -0.18 | F12: 0.118
A13: D6 | B13: HMOs+GOS | C13: 4.8 | D13: 4.49 | E13: =D13-C13 -> -0.31 | F13: 0.17209999
... A168: D8 | B168: HMOs+fuc+lac+muc | C168: 5.8 | D168: 3.93 | E168: =D168-C168 -> -1.87 | F168: 0.96049999
A169: D8 | B169: HMOs+fuc+lac+muc | C169: 5.8 | E169: =D169-C169 -> -5.8 | F169: 0.98240005
A170: D8 | B170: HMOs+fuc+lac+muc+GOS | C170: 5.8 | D170: 3.97 | E170: =D170-C170 -> -1.83 | F170: 0.96489995
A171: D8 | B171: HMOs+fuc+lac+muc+GOS | C171: 5.8 | D171: 3.95 | E171: =D171-C171 -> -1.85 | F171: 1.0184
A172: D8 | B172: HMOs+fuc+lac+muc+GOS | C172: 5.8 | D172: 3.95 | E172: =D172-C172 -> -1.85 | F172: 1.0347
A173: D8 | B173: HMOs+fuc+lac+muc+GOS+6c | C173: 5.8 | D173: 3.95 | E173: =D173-C173 -> -1.85 | F173: 1.2056999
A174: D8 | B174: HMOs+fuc+lac+muc+GOS+6c | C174: 5.8 | D174: 3.97 | E174: =D174-C174 -> -1.83 | F174: 1.1348
A175: D8 | B175: HMOs+fuc+lac+muc+GOS+6c | C175: 5.8 | D175: 3.97 | E175: =D175-C175 -> -1.83 | F175: 1.1176
A176: D8 | B176: muc+6c | C176: 5.8 | D176: 5.55 | E176: =D176-C176 -> -0.25 | F176: 0.3737
A177: D8 | B177: muc+6c | C177: 5.8 | D177: 5.57 | E177: =D177-C177 -> -0.23 | F177: 0.3665
A178: D8 | B178: muc+6c | C178: 5.8 | D178: 5.58 | E178: =D178-C178 -> -0.22 | F178: 0.37720001
A179: D8 | B179: HMOs+muc+6c | C179: 5.8 | D179: 5.24 | E179: =D179-C179 -> -0.56 | F179: 0.45870001
A180: D8 | B180: HMOs+muc+6c | C180: 5.8 | D180: 5.24 | E180: =D180-C180 -> -0.56 | F180: 0.45859999
A181: D8 | B181: HMOs+muc+6c | C181: 5.8 | D181: 5.26 | E181: =D181-C181 -> -0.54 | F181: 0.46230001

Sheet OD+DNA.conc.
A1: Mean Corrected OD | B1: DNA conc. | C1: initial pH | D1: Supplement mix | E1: Donor
A2: =AVERAGE(OFFSET('OD+pH'!$F$2,(ROW()-ROW($A$2))*3,,3)) -> -0.021766669 | B2: 3.1352966 | C2: 4.8 | D2: H2O | E2: D6
A3: =AVERAGE(OFFSET('OD+pH'!$F$2,(ROW()-ROW($A$2))*3,,3)) -> 0.074433337 | B3: 1.8336875 | C3: 4.8 | D3: HMOs | E3: D6
A4: =AVERAGE(OFFSET('OD+pH'!$F$2,(ROW()-ROW($A$2))*3,,3)) -> 0.14173333 | B4: 6.6475234 | C4: 4.8 | D4: GOS | E4: D6
A5: =AVERAGE(OFFSET('OD+pH'!$F$2,(ROW()-ROW($A$2))*3,,3)) -> 0.14699999 | B5: 2.600969 | C5: 4.8 | D5: HMOs+GOS | E5: D6
A6: =AVERAGE(OFFSET('OD+pH'!$F$2,(ROW()-ROW($A$2))*3,,3)) -> 0.16433334 | B6: 26.608244 | C6: 4.8 | D6: HMOs+GOS+muc | E6: D6
A7: =AVERAGE(OFFSET('OD+pH'!$F$2,(ROW()-ROW($A$2))*3,,3)) -> 0.14496666 | B7: 6.4324891 | C7: 4.8 | D7: HMOs+fuc+lac+muc | E7: D6
A8: =AVERAGE(OFFSET('OD+pH'!$F$2,(ROW()-ROW($A$2))*3,,3)) -> 0.14363333 | B8: 2.3810476 | C8: 4.8 | D8: HMOs+fuc+lac+muc+GOS | E8: D6
A9: =AVERAGE(OFFSET('OD+pH'!$F$2,(ROW()-ROW($A$2))*3,,3)) -> 0.22689999 | B9: 11.516747 | C9: 4.8 | D9: HMOs+fuc+lac+muc+GOS+6c | E9: D6
A10: =AVERAGE(OFFSET('OD+pH'!$F$2,(ROW()-ROW($A$2))*3,,3)) -> 0.092466675 | B10: 3.9742562 | C10: 4.8 | D10: muc+6c | E10: D6
A11: =AVERAGE(OFFSET('OD+pH'!$F$2,(ROW()-ROW($A$2))*3,,3)) -> 0.12036667 | B11: 4.585149 | C11: 4.8 | D11: HMOs+muc+6c | E11: D6
A12: =AVERAGE(OFFSET('OD+pH'!$F$2,(ROW()-ROW($A$2))*3,,3)) -> 0.0587 | B12: 25.814898 | C12: 5.8 | D12: H2O | E12: D6
A13: =AVERAGE(OFFSET('OD+pH'!$F$2,(ROW()-ROW($A$2))*3,,3)) -> 0.68723335 | B13: 38.133756 | C13: 5.8 | D13: HMOs | E13: D6
... A61: =AVERAGE(OFFSET('OD+pH'!$F$2,(ROW()-ROW($A$2))*3,,3)) -> 0.45986667 | B61: 145.95228 | C61: 5.8 | D61: HMOs+muc+6c | E61: D8

Sheet qPCR_All
A1: Position (qPCR plate) | B1: Sample name | C1: Supplement mix | D1: Mucin | E1: GOS | F1: 6c | G1: HMOs | H1: Fuc Lac | I1: pH | J1: Donor | K1: Copies ITS/mL | L1: Copies 16S/mL | M1: Bifido/mL | N1: Entero/mL
A2: P1-A1 | B2: S1 | C2: H2O | D2: 0 | E2: 0 | F2: 0 | G2: 0 | H2: 0 | I2: 4.8 | J2: D6 | K2: 1542815 | L2: 1.1136876e+10 | M2: 629386.77 | N2: 290463.75
A3: P1-A2 | B3: S1 | C3: H2O | D3: 0 | E3: 0 | F3: 0 | G3: 0 | H3: 0 | I3: 4.8 | J3: D6 | K3: 1532597.7 | L3: 1.0728184e+10 | M3: 584430.58 | N3: 237917.54
A4: P1-A3 | B4: S1 | C4: H2O | D4: 0 | E4: 0 | F4: 0 | G4: 0 | H4: 0 | I4: 4.8 | J4: D6 | K4: 1461076.4 | L4: 1.0319491e+10 | M4: 574213.26 | N4: 258352.18
A5: P1-A4 | B5: S2 | C5: HMOs | D5: 0 | E5: 0 | F5: 0 | G5: 1 | H5: 0 | I5: 4.8 | J5: D6 | K5: 1605585.7 | L5: 8.6852488e+09 | M5: 74137.111 | N5: 148089.5
A6: P1-A5 | B6: S2 | C6: HMOs | D6: 0 | E6: 0 | F6: 0 | G6: 1 | H6: 0 | I6: 4.8 | J6: D6 | K6: 1465501 | L6: 7.9848255e+09 | M6: 69826.814 | N6: 133465.27
A7: P1-A6 | B7: S2 | C7: HMOs | D7: 0 | E7: 0 | F7: 0 | G7: 1 | H7: 0 | I7: 4.8 | J7: D6 | K7: 1594809.9 | L7: 7.499917e+09 | M7: 71766.448 | N7: 139007.08
A8: P1-A7 | B8: S3 | C8: GOS | D8: 0 | E8: 1 | F8: 0 | G8: 0 | H8: 0 | I8: 4.8 | J8: D6 | K8: 2734965.8 | L8: 3.0406384e+10 | M8: 68535.025 | N8: 475746.15
A9: P1-A8 | B9: S3 | C9: GOS | D9: 0 | E9: 1 | F9: 0 | G9: 0 | H9: 0 | I9: 4.8 | J9: D6 | K9: 2718877.7 | L9: 2.6384376e+10 | M9: 64673.897 | N9: 406797.43
A10: P1-A9 | B10: S3 | C10: GOS | D10: 0 | E10: 1 | F10: 0 | G10: 0 | H10: 0 | I10: 4.8 | J10: D6 | K10: 2670613.6 | L10: 2.5419094e+10 | M10: 66604.461 | N10: 457359.82
A11: P1-A10 | B11: S4 | C11: HMOs+GOS | D11: 0 | E11: 1 | F11: 0 | G11: 1 | H11: 0 | I11: 4.8 | J11: D6 | K11: 1878724.6 | L11: 1.8018177e+10 | M11: 2614833 | N11: 282514.97
A12: P1-A11 | B12: S4 | C12: HMOs+GOS | D12: 0 | E12: 1 | F12: 0 | G12: 1 | H12: 0 | I12: 4.8 | J12: D6 | K12: 2032538.3 | L12: 1.7249109e+10 | M12: 2100655.8 | N12: 274667.34
A13: P1-A12 | B13: S4 | C13: HMOs+GOS | D13: 0 | E13: 1 | F13: 0 | G13: 1 | H13: 0 | I13: 4.8 | J13: D6 | K13: 1878724.6 | L13: 1.8128044e+10 | M13: 1865540.5 | N13: 282514.97
... A73: P1-F12 | B73: S54 | C73: HMOs+GOS | D73: 0 | E73: 1 | F73: 0 | G73: 1 | H73: 0 | I73: 5.8 | J73: D8 | K73: 8520579.2 | L73: 4.5421241e+11 | M73: 9.0187053e+08 | N73: 1.2453154e+08
A74: P1-G1 | B74: S61 | C74: Raw feces | I74: Raw feces | J74: D6 | K74: 1693205.7 | L74: 1.5509195e+10 | M74: 82810565 | N74: 2.3172323e+08
A75: P1-G2 | B75: S61 | C75: Raw feces | I75: Raw feces | J75: D6 | K75: 1707434.3 | L75: 1.401519e+10 | M75: 78826551 | N75: 2.1952727e+08
A76: P1-G3 | B76: S61 | C76: Raw feces | I76: Raw feces | J76: D6 | K76: 2091607.1 | L76: 1.5082337e+10 | M76: 78257407 | N76: 2.2969057e+08
A77: P1-G4 | B77: S61 | C77: Raw feces | I77: Raw feces | J77: D6 | K77: 1998213.7 | L77: 9.9761565e+09 | M77: 43841405 | N77: 1.6658882e+08
A78: P1-G5 | B78: S61 | C78: Raw feces | I78: Raw feces | J78: D6 | K78: 1789445.1 | L78: 9.3349387e+09 | M78: 40858997 | N78: 1.6360641e+08
A79: P1-G6 | B79: S61 | C79: Raw feces | I79: Raw feces | J79: D6 | K79: 1685060.8 | L79: 9.3796748e+09 | M79: 46823814 | N79: 1.6041097e+08
A80: P1-G7 | B80: S62 | C80: Raw feces | I80: Raw feces | J80: D7 | K80: 2947504.3 | L80: 4.7214652e+10 | M80: 56220915 | N80: 1.0292872e+08
A81: P1-G8 | B81: S62 | C81: Raw feces | I81: Raw feces | J81: D7 | K81: 4339381.3 | L81: 0 | M81: 55675081 | N81: 1.0448825e+08
A82: P1-G9 | B82: S62 | C82: Raw feces | I82: Raw feces | J82: D7 | K82: 3520630.1 | L82: 3.1112545e+10 | M82: 61679256 | N82: 1.0526801e+08
A83: P1-G10 | B83: S62 | C83: Raw feces | I83: Raw feces | J83: D7 | K83: 3038290.8 | L83: 1.9141232e+11 | M83: 74944507 | N83: 1.2334014e+08
A84: P1-G11 | B84: S62 | C84: Raw feces | I84: Raw feces | J84: D7 | K84: 3848501.7 | L84: 4.9372226e+10 | M84: 72918979 | N84: 1.2008483e+08
A85: P1-G12 | B85: S62 | C85: Raw feces | I85: Raw feces | J85: D7 | K85: 3063609.9 | L85: 4.3548835e+10 | M85: 68867925 | N85: 1.1574441e+08
A86: P2-A1 | B86: S5 | C86: HMOs+GOS+muc | D86: 1 | E86: 1 | F86: 0 | G86: 1 | H86: 0 | I86: 4.8 | J86: D6 | K86: 6083890.4 | L86: 2.1604019e+11 | M86: 2.8060392e+08 | N86: 1850590.6
A87: P2-A2 | B87: S5 | C87: HMOs+GOS+muc | D87: 1 | E87: 1 | F87: 0 | G87: 1 | H87: 0 | I87: 4.8 | J87: D6 | K87: 5752794.3 | L87: 1.8748315e+11 | M87: 2.9219229e+08 | N87: 1933364.6
A88: P2-A3 | B88: S5 | C88: HMOs+GOS+muc | D88: 1 | E88: 1 | F88: 0 | G88: 1 | H88: 0 | I88: 4.8 | J88: D6 | K88: 6001116.4 | L88: 1.6347869e+11 | M88: 2.9053681e+08 | N88: 1826940.8
A89: P2-A4 | B89: S6 | C89: HMOs+fuc+lac+muc | D89: 1 | E89: 0 | F89: 0 | G89: 1 | H89: 1 | I89: 4.8 | J89: D6 | K89: 1943572.2 | L89: 2.8648759e+10 | M89: 3155149.7 | N89: 378617.96
A90: P2-A5 | B90: S6 | C90: HMOs+fuc+lac+muc | D90: 1 | E90: 0 | F90: 0 | G90: 1 | H90: 1 | I90: 4.8 | J90: D6 | K90: 1829986.8 | L90: 4.5938979e+10 | M90: 3129908.5 | N90: 380420.9
A91: P2-A6 | B91: S6 | C91: HMOs+fuc+lac+muc | D91: 1 | E91: 0 | F91: 0 | G91: 1 | H91: 1 | I91: 4.8 | J91: D6 | K91: 1905710.4 | L91: 3.2434939e+10 | M91: 3079426.1 | N91: 400253.27
A92: P2-A7 | B92: S7 | C92: HMOs+fuc+lac+muc+GOS | D92: 1 | E92: 1 | F92: 0 | G92: 1 | H92: 1 | I92: 4.8 | J92: D6 | K92: 993792.34 | L92: 1.0230215e+10 | M92: 1651449 | N92: 181638.52
A93: P2-A8 | B93: S7 | C93: HMOs+fuc+lac+muc+GOS | D93: 1 | E93: 1 | F93: 0 | G93: 1 | H93: 1 | I93: 4.8 | J93: D6 | K93: 1023021.5 | L93: 1.0010996e+10 | M93: 1592990.7 | N93: 175375.12
A94: P2-A9 | B94: S7 | C94: HMOs+fuc+lac+muc+GOS | D94: 1 | E94: 1 | F94: 0 | G94: 1 | H94: 1 | I94: 4.8 | J94: D6 | K94: 1015714.2 | L94: 1.0084069e+10 | M94: 1519917.7 | N94: 171199.52
A95: P2-A10 | B95: S8 | C95: HMOs+fuc+lac+muc+GOS+6c | D95: 1 | E95: 1 | F95: 1 | G95: 1 | H95: 1 | I95: 4.8 | J95: D6 | K95: 3178363.6 | L95: 7.5806933e+10 | M95: 3766657 | N95: 927845.28
A96: P2-A11 | B96: S8 | C96: HMOs+fuc+lac+muc+GOS+6c | D96: 1 | E96: 1 | F96: 1 | G96: 1 | H96: 1 | I96: 4.8 | J96: D6 | K96: 2980949.7 | L96: 6.9489689e+10 | M96: 3841674.3 | N96: 899643.29
A97: P2-A12 | B97: S8 | C97: HMOs+fuc+lac+muc+GOS+6c | D97: 1 | E97: 1 | F97: 1 | G97: 1 | H97: 1 | I97: 4.8 | J97: D6 | K97: 3079656.7 | L97: 6.0211236e+10 | M97: 3273122.3 | N97: 868621.11
... A157: P2-F12 | B157: S58 | C157: HMOs+fuc+lac+muc+GOS+6c | D157: 1 | E157: 1 | F157: 1 | G157: 1 | H157: 1 | I157: 5.8 | J157: D8 | K157: 4426265.3 | L157: 1.0754185e+11 | M157: 6.1967714e+08 | N157: 2.6136043e+08
A158: P2-G1 | B158: S63 | C158: Raw feces | I158: Raw feces | J158: D8 | K158: 8947792.6 | L158: 4.3404209e+10 | M158: 1.7579199e+08 | N158: 4.0113229e+09
...

Sheet OD_Entero
A1: Mean Bacteria/mL | B1: initial pH | C1: Supplement mix | D1: Donor | E1: Mean Corrected OD
A2: 262244.49 | B2: 4.8 | C2: H2O | D2: D6 | E2: -0.021766669
A3: 140187.28 | B3: 4.8 | C3: HMOs | D3: D6 | E3: 0.074433337
A4: 446634.47 | B4: 4.8 | C4: GOS | D4: D6 | E4: 0.14173333
A5: 279899.1 | B5: 4.8 | C5: HMOs+GOS | D5: D6 | E5: 0.14699999
A6: 6.1829381e+09 | B6: 5.8 | C6: H2O | D6: D6 | E6: 0.0587
A7: 7.8018786e+08 | B7: 5.8 | C7: HMOs | D7: D6 | E7: 0.68723335
A8: 20224020 | B8: 5.8 | C8: GOS | D8: D6 | E8: 1.0250667
A9: 41572335 | B9: 5.8 | C9: HMOs+GOS | D9: D6 | E9: 0.86819999
A10: 9.1829358e+08 | B10: 4.8 | C10: H2O | D10: D7 | E10: 0.041699998
A11: 830.11939 | B11: 4.8 | C11: HMOs | D11: D7 | E11: 0.04443333
A12: 1311.3311 | B12: 4.8 | C12: GOS | D12: D7 | E12: 0.045466666
A13: 1286.9104 | B13: 4.8 | C13: HMOs+GOS | D13: D7 | E13: 0.045999999
... A61: 2.6187036e+09 | B61: 5.8 | C61: HMOs+muc+6c | D61: D8 | E61: 0.45986667

Sheet Heatmap
A1: initial pH | B1: Supplement mix | C1: Mucin | D1: GOS | E1: 6c | F1: HMOs | G1: Fuc Lac | H1: Donor | I1: Mean ITS/mL | J1: Mean 16S/mL | K1: Mean Bifido/mL | L1: Mean Entero/mL | M1: Mean Corrected OD | N1: DNA conc.
A2: 4.8 | B2: H2O | C2: 0 | D2: 0 | E2: 0 | F2: 0 | G2: 0 | H2: D6 | I2: 1512163 | J2: 1.0728184e+10 | K2: 596010.2 | L2: 262244.49 | M2: -0.021766669 | N2: 3.1352966
A3: 4.8 | B3: HMOs | C3: 0 | D3: 0 | E3: 0 | F3: 1 | G3: 0 | H3: D6 | I3: 1555298.9 | J3: 8.0566638e+09 | K3: 71910.124 | L3: 140187.28 | M3: 0.074433337 | N3: 1.8336875
A4: 4.8 | B4: GOS | C4: 0 | D4: 1 | E4: 0 | F4: 0 | G4: 0 | H4: D6 | I4: 2708152.4 | J4: 2.7403285e+10 | K4: 66604.461 | L4: 446634.47 | M4: 0.14173333 | N4: 6.6475234
A5: 4.8 | B5: HMOs+GOS | C5: 0 | D5: 1 | E5: 0 | F5: 1 | G5: 0 | H5: D6 | I5: 1929995.8 | J5: 1.7798443e+10 | K5: 2193676.5 | L5: 279899.1 | M5: 0.14699999 | N5: 2.600969
A6: 5.8 | B6: H2O | C6: 0 | D6: 0 | E6: 0 | F6: 0 | G6: 0 | H6: D6 | I6: 5362435 | J6: 1.5937592e+11 | K6: 76707319 | L6: 6.1829381e+09 | M6: 0.0587 | N6: 25.814898
A7: 5.8 | B7: HMOs | C7: 0 | D7: 0 | E7: 0 | F7: 1 | G7: 0 | H7: D6 | I7: 11929051 | J7: 4.2388093e+11 | K7: 7.5659194e+08 | L7: 7.8018786e+08 | M7: 0.68723335 | N7: 38.133756
A8: 5.8 | B8: GOS | C8: 0 | D8: 1 | E8: 0 | F8: 0 | G8: 0 | H8: D6 | I8: 15528988 | J8: 7.5335671e+11 | K8: 1.0622631e+09 | L8: 20224020 | M8: 1.0250667 | N8: 50.721408
A9: 5.8 | B9: HMOs+GOS | C9: 0 | D9: 1 | E9: 0 | F9: 1 | G9: 0 | H9: D6 | I9: 20193953 | J9: 4.8761007e+11 | K9: 1.7058144e+09 | L9: 41572335 | M9: 0.86819999 | N9: 69.385407
A10: 4.8 | B10: H2O | C10: 0 | D10: 0 | E10: 0 | F10: 0 | G10: 0 | H10: D7 | I10: 23855226 | J10: 2.8283442e+10 | K10: 9713505.4 | L10: 9.1829358e+08 | M10: 0.041699998 | N10: 0.72175754
A11: 4.8 | B11: HMOs | C11: 0 | D11: 0 | E11: 0 | F11: 1 | G11: 0 | H11: D7 | I11: 644984.85 | J11: 56257012 | K11: 26516.044 | L11: 830.11939 | M11: 0.04443333 | N11: -0.17719097
A12: 4.8 | B12: GOS | C12: 0 | D12: 1 | E12: 0 | F12: 0 | G12: 0 | H12: D7 | I12: 1012248.1 | J12: 40399813 | K12: 146941.18 | L12: 1311.3311 | M12: 0.045466666 | N12: -0.17816097
A13: 4.8 | B13: HMOs+GOS | C13: 0 | D13: 1 | E13: 0 | F13: 1 | G13: 0 | H13: D7 | I13: 1281823.8 | J13: 35994649 | K13: 45899.651 | L13: 1286.9104 | M13: 0.045999999 | N13: -0.1973185
... A61: 5.8 | B61: HMOs+muc+6c | C61: 1 | D61: 0 | E61: 1 | F61: 1 | G61: 0 | H61: D8 | I61: 4276945.8 | J61: 6.3101151e+11 | K61: 6.658427e+08 | L61: 2.6187036e+09 | M61: 0.45986667 | N61: 145.95228
